Workbook

Sheet Sheet2
A2: New Project Request/Pricing Form
A6: Name of Project | C6: =IF(Sheet1!B3=0,"",Sheet1!B3) | I6: Submit Date: | L6: =IF(Sheet1!B4=0,"",Sheet1!B4)
A7: Submitter | C7: =IF(Sheet1!B5=0,"",Sheet1!B5) | I7: Project Start Date: | L7: =IF(Sheet1!B7=0,"",Sheet1!B7)
A8: Project Description:
A9: =IF(Sheet1!B8=0,"",Sheet1!B8)
A11: A. File Transmission & Types
A12: Files transmitted via: | C12: =IF(D12=Sheet1!B9,"x","") | D12: Client FTP | E12: =IF(F12=Sheet1!B9,"x","") | F12: CoreLogic FTP | H12: =IF(I12=Sheet1!B9,"x","") | I12: CL Pull from Client System Imaging | K12: =IF(L12=Sheet1!B9,"x","") | L12: Other (Explain below)
L13: Mortgage Cadence integration
B14: How many times will Corelogic be sweeping the SFTP | H14: =IF(I14=Sheet1!B10,"x","") | I14: 2X | K14: =IF(L14=Sheet1!B10,"x","") | L14: 4X
B15: What times of day (EST) will the sweeps take place?
B16: =IF(Sheet1!B11=0,"",Sheet1!B11)
A18: Type of Files | C18: =IF(D18=Sheet1!B12,"x","") | D18: PDF | E18: =IF(F18=Sheet1!B12,"x","") | F18: HP | H18: =IF(I18=Sheet1!B12,"x","") | I18: TIFF | K18: =IF(L18=Sheet1!B12,"x","") | L18: Other (Explain below)
A20: B. File Receipt & Service Levels
A21: What time will files be transmitted to CoreLogic? | F21: =Sheet1!B13 -> 0
F22: Please specify time of day here: | K22: =IF(Sheet1!B13=0,"",Sheet1!B13)
A24: Service Level | B24: Service Level | C24: =IF(D24=Sheet1!B14,"x","") | D24: Same Day | E24: =IF(F24=Sheet1!B14,"x","") | F24: 24 Hours | H24: =IF(I24=Sheet1!B14,"x","") | I24: 48 Hours | K24: =IF(OR(C24="x",E24="x",H24="x"),"","x") -> x | L24: Other (Explain below)
A25: =IF(IF(OR(C24="x",E24="x",H24="x"),"",Sheet1!B14)=0,"",Sheet1!B14)
A27: Est. pages per Package: | D27: =Sheet1!B15 -> 0 | F27: Estimated # of Packages Per Month: | L27: =Sheet1!B17 -> 0
A28: Est. # of Packages Per Day: | D28: =Sheet1!B16 -> 0 | F28: Estimated # of Packages Annually: | L28: =Sheet1!B18 -> 0
A31: C. Daily Print Schedule
A32: =IF(ISNUMBER(SEARCH(B32,Sheet1!B19)),"x","") | B32: Monday | C32: =IF(ISNUMBER(SEARCH(D32,Sheet1!B19)),"x","") | D32: Tuesday | E32: =IF(ISNUMBER(SEARCH(F32,Sheet1!B19)),"x","") | F32: Wednesday | H32: =IF(ISNUMBER(SEARCH(I32,Sheet1!B19)),"x","") | I32: Thursday | K32: =IF(ISNUMBER(SEARCH(L32,Sheet1!B19)),"x","") | L32: Friday
A33: =IF(ISNUMBER(SEARCH(B33,Sheet1!B19)),"x","") | B33: Saturday | C33: =IF(ISNUMBER(SEARCH(D33,Sheet1!B19)),"x","") | D33: Sunday
A35: D. Project Requirements: Paper & Print (Check all that apply)
A37: =IF(ISNUMBER(SEARCH(B37,Sheet1!B21)),"x","") | B37: Mixed Media | C37: =IF(ISNUMBER(SEARCH(D37,Sheet1!B21)),"x","") | D37: Letter Only | E37: =IF(ISNUMBER(SEARCH(F37,Sheet1!B21)),"x","") | F37: Legal Only | H37: =IF(ISNUMBER(SEARCH(I37,Sheet1!B21)),"x","") | I37: Stapled | K37: =IF(ISNUMBER(SEARCH(L37,Sheet1!B21)),"x","") | L37: Not Stapled
A39: =IF(ISNUMBER(SEARCH(B39,Sheet1!B21)),"x","") | B39: 24# Paper | C39: =IF(ISNUMBER(SEARCH(D39,Sheet1!B21)),"x","") | D39: Insert Required | E39: =IF(ISNUMBER(SEARCH(F39,Sheet1!B21)),"x","") | F39: White | H39: =IF(ISNUMBER(SEARCH(I39,Sheet1!B21)),"x","") | I39: Color (please specify)
A41: =IF(ISNUMBER(SEARCH(B41,Sheet1!B21)),"x","") | B41: Print 1-sided | C41: =IF(ISNUMBER(SEARCH(D41,Sheet1!B21)),"x","") | D41: Print 2-sided | E41: =IF(ISNUMBER(SEARCH(F41,Sheet1!B21)),"x","") | F41: B&W | H41: =IF(ISNUMBER(SEARCH(I41,Sheet1!B21)),"x","") | I41: Color | K41: =IF(ISNUMBER(SEARCH(L41,Sheet1!B21)),"x","") | L41: B&W & Color
A43: E. How are packages to be sent for the customer:
A45: =IF(B45=Sheet1!B23,"x","") | B45: Mailed-USPS | C45: =IF(D45=Sheet1!B23,"x","") | D45: Federal Express | H45: =IF(I45=Sheet1!B23,"x","") | I45: Certified USPS
A47: =IF(OR(C45="x",A45="x",H45="x"),"","x") -> x | B47: Other (please specify below) | D47: First Mortgage will sent through Federal Express and Equity line of credit will go out in USPS
D48: =IF(IF(OR(A45="x",C45="x",H45="x"),"",Sheet1!B14)=0,"",Sheet1!B14)
A49: F. Envelopes
A50: If mailed, what type of envelope is required? | H50: =IF(Sheet1!B24="True","x","") | I50: Sample envelope(s) attached?
A52: =IF(B52=Sheet1!B25,"x","") | B52: # 10 | C52: =IF(D52=Sheet1!B25,"x","") | D52: 6 x 9.5 | E52: =IF(F52=Sheet1!B25,"x","") | F52: 9 x 12 | H52: =IF(I52=Sheet1!B25,"x","") | I52: 10 x 12 | K52: =IF(L52=Sheet1!B25,"x","") | L52: Standard Window
A54: =IF(B54=Sheet1!B25,"x","") | B54: 10 x 13 | C54: =IF(OR(A52="x",C52="x",E52="x",H52="x",K52="x",A54="x",K54="x"),"","x") -> x | D54: Other (Specify): | F54: =IF(IF(OR(A52="x",C52="x",E52="x",H52="x",K52="x",A54="x",K54="x"),"",Sheet1!B25)=0,"",Sheet1!B25) | K54: =IF(L54=Sheet1!B25,"x","") | L54: Custom Window(s)
A56: Does it need a Business Reply Mail envelope included? | H56: =IF(I56=Sheet1!B27,"x","") | I56: No
A58: =IF(B58=Sheet1!B27,"x","") | B58: #9 Business Reply Mail | C58: =IF(OR(A58="x",H56="x"),"","x") -> x | D58: Other Business Reply Mail? Specify below:
D59: =IF(IF(OR(A58="x",H56="x"),"",Sheet1!B27)=0,"",Sheet1!B27)
A62: Will customer supply their envelopes? | H62: =IF(Sheet1!B28="True","x","") | I62: Yes | K62: =IF(Sheet1!B28="False","x","") | L62: No
A64: Will customer provide artwork for the envelope(s)? | H64: =IF(Sheet1!B29="True","x","") | I64: Yes | K64: =IF(Sheet1!B29="False","x","") | L64: No
A65: Note: If custom envelope is required, please allow 3-4 weeks for delivery
...

Sheet Sheet1
