Workbook

Sheet Sheet2
A2: New Project Request/Pricing Form
A6: Name of Project: | C6: =IF(Sheet1!B3=0,"",Sheet1!B3) | I6: Submit Date: | L6: =IF(Sheet1!B4=0,"",Sheet1!B4)
A8: Submitter: | C8: =IF(Sheet1!B5=0,"",Sheet1!B5) | I8: Project Start Date: | L8: =IF(Sheet1!B7=0,"",Sheet1!B7)
A10: Project Description: | C10: =IF(Sheet1!B8=0,"",Sheet1!B8)
A13: A. File Transmission & Types
A14: Files transmitted via: | C14: =IF(ISNUMBER(SEARCH(D14,Sheet1!B9)),"x","") | D14: Client FTP | E14: =IF(ISNUMBER(SEARCH(F14,Sheet1!B9)),"x","") | F14: CoreLogic FTP | H14: =IF(ISNUMBER(SEARCH(I14,Sheet1!B9)),"x","") | I14: CL Pull from Client System Imaging | K14: =IF(ISNUMBER(SEARCH(L14,Sheet1!B9)),"x","") | L14: Mortgage Cadence Integration
B16: Other | C16: =IF(ISNUMBER(SEARCH(B16,Sheet1!B9)),"x","") | E16: =IF(Sheet1!B39=0,"",Sheet1!B39)
B18: How many times will Corelogic be sweeping the SFTP | H18: =IF(I18=Sheet1!B11,"x","") | I18: 2X | K18: =IF(L18=Sheet1!B11,"x","") | L18: 4X
B20: What times of day (EST) will the sweeps take place? | G20: =IF(Sheet1!B12=0,"",Sheet1!B12)
A22: Type of Files | C22: =IF(ISNUMBER(SEARCH(D22,Sheet1!B13)),"x","") | D22: PDF | E22: =IF(ISNUMBER(SEARCH(F22,Sheet1!B13)),"x","") | F22: HP | H22: =IF(ISNUMBER(SEARCH(I22,Sheet1!B13)),"x","") | I22: TIFF | K22: =IF(ISNUMBER(SEARCH(L22,Sheet1!B13)),"x","") | L22: Other
I23: =IF(Sheet1!B40=0,"",Sheet1!B40)
A24: B. File Receipt & Service Levels
A25: What time will files be transmitted to CoreLogic? | H25: =IF(ISNUMBER(SEARCH(I25,Sheet1!B15)),"x","") | I25: AM | K25: =IF(ISNUMBER(SEARCH(L25,Sheet1!B15)),"x","") | L25: PM
A28: Service Level | B28: Service Level | C28: =IF(ISNUMBER(SEARCH(D28,Sheet1!B17)),"x","") | D28: Same Day | E28: =IF(ISNUMBER(SEARCH(F28,Sheet1!B17)),"x","") | F28: 24 Hours | H28: =IF(ISNUMBER(SEARCH(I28,Sheet1!B17)),"x","") | I28: 48 Hours | K28: =IF(ISNUMBER(SEARCH(L28,Sheet1!B17)),"x","") | L28: Other
A29: =IF(Sheet1!B58=0,"",Sheet1!B58)
A31: Est. pages per Package: | D31: =Sheet1!B19 -> 0 | F31: Estimated # of Packages Per Month: | L31: =Sheet1!B21 -> 0
A32: Est. # of Packages Per Day: | D32: =Sheet1!B20 -> 0 | F32: Estimated # of Packages Annually: | L32: =Sheet1!B22 -> 0
A35: C. Daily Print Schedule
A36: =IF(ISNUMBER(SEARCH(B36,Sheet1!B23)),"x","") | B36: Monday | C36: =IF(ISNUMBER(SEARCH(D36,Sheet1!B23)),"x","") | D36: Tuesday | E36: =IF(ISNUMBER(SEARCH(F36,Sheet1!B23)),"x","") | F36: Wednesday | H36: =IF(ISNUMBER(SEARCH(I36,Sheet1!B23)),"x","") | I36: Thursday | K36: =IF(ISNUMBER(SEARCH(L36,Sheet1!B23)),"x","") | L36: Friday
A37: =IF(ISNUMBER(SEARCH(B37,Sheet1!B23)),"x","") | B37: Saturday | C37: =IF(ISNUMBER(SEARCH(D37,Sheet1!B23)),"x","") | D37: Sunday
A39: D. Project Requirements: Paper & Print (Check all that apply)
A41: =IF(ISNUMBER(SEARCH(B41,Sheet1!B25)),"x","") | B41: Mixed Media | C41: =IF(ISNUMBER(SEARCH(D41,Sheet1!B25)),"x","") | D41: Letter Only | E41: =IF(ISNUMBER(SEARCH(F41,Sheet1!B25)),"x","") | F41: Legal Only | H41: =IF(ISNUMBER(SEARCH(I41,Sheet1!B25)),"x","") | I41: Stapled | K41: =IF(ISNUMBER(SEARCH(L41,Sheet1!B25)),"x","") | L41: Not Stapled
A43: =IF(ISNUMBER(SEARCH(B43,Sheet1!B25)),"x","") | B43: 24# Paper | C43: =IF(ISNUMBER(SEARCH(D43,Sheet1!B25)),"x","") | D43: Insert Required | E43: =IF(ISNUMBER(SEARCH(F43,Sheet1!B25)),"x","") | F43: White | H43: =IF(ISNUMBER(SEARCH(I43,Sheet1!B25)),"x","") | I43: Color (specify) | L43: =IF(Sheet1!B59=0,"",Sheet1!B59)
A45: =IF(ISNUMBER(SEARCH(B45,Sheet1!B25)),"x","") | B45: Print 1-sided | C45: =IF(ISNUMBER(SEARCH(D45,Sheet1!B25)),"x","") | D45: Print 2-sided | E45: =IF(ISNUMBER(SEARCH(F45,Sheet1!B25)),"x","") | F45: B&W | H45: =IF(ISNUMBER(SEARCH(I45,Sheet1!B25)),"x","") | I45: Color | K45: =IF(ISNUMBER(SEARCH(L45,Sheet1!B25)),"x","") | L45: B&W & Color
A47: E. How are packages to be sent for the customer:
A49: =IF(ISNUMBER(SEARCH(B49,Sheet1!B27)),"x","") | B49: Mailed-USPS | C49: =IF(ISNUMBER(SEARCH(D49,Sheet1!B27)),"x","") | D49: Federal Express | H49: =IF(ISNUMBER(SEARCH(I49,Sheet1!B27)),"x","") | I49: Certified USPS
A51: =IF(ISNUMBER(SEARCH(B51,Sheet1!B27)),"x","") | B51: Other
B52: =IF(Sheet1!B60=0,"",Sheet1!B60)
A53: F. Envelopes
A54: If mailed, what type of envelope is required? | H54: =IF(Sheet1!I54="True","x","") | I54: Sample envelope(s) attached?
A56: =IF(ISNUMBER(SEARCH(B56,Sheet1!B30)),"x","") | B56: # 10 | C56: =IF(ISNUMBER(SEARCH(D56,Sheet1!B30)),"x","") | D56: 6 x 9.5 | E56: =IF(ISNUMBER(SEARCH(F56,Sheet1!B30)),"x","") | F56: 9 x 12 | H56: =IF(ISNUMBER(SEARCH(I56,Sheet1!B30)),"x","") | I56: 10 x 12 | K56: =IF(ISNUMBER(SEARCH(L56,Sheet1!B30)),"x","") | L56: 10 x 13
A58: =IF(ISNUMBER(SEARCH(B58,Sheet1!B30)),"x","") | B58: Other | D58: =IF(Sheet1!B61=0,"",Sheet1!B61)
A60: Does it need a Business Reply Mail envelope included? | H60: =IF(I60=Sheet1!B33,"x","") | I60: Yes | K60: =IF(L60=Sheet1!B33,"x","") | L60: No
A62: =IF(B62=Sheet1!B33,"x","") | B62: #9 Business Reply Mail | C62: =IF(D62=Sheet1!B33,"x","") | D62: Other
D63: =IF(Sheet1!B62=0,"",Sheet1!B62)
A66: Will customer supply their envelopes? | H66: =IF(Sheet1!B35="True","x","") | I66: Yes | K66: =IF(Sheet1!B35="False","x","") | L66: No
A68: Will customer provide artwork for the envelope(s)? | H68: =IF(Sheet1!B36="True","x","") | I68: Yes | K68: =IF(Sheet1!B36="False","x","") | L68: No
A69: Note: If custom envelope is required, please allow 3-4 weeks for delivery
A71: G. Postage *
A73: Do you have an active general permit number if USPS is the preferred shipping method | H73: =IF(Sheet1!B37="True","x","") | I73: Yes | K73: =IF(Sheet1!B37="False","x","") | L73: No
...

Sheet Sheet1
